Workbook

Sheet Sheet1
A1: تاریخ | B1: نماد | C1: قیمت پایانی | D1: حجم | E1: ارزش معاملات | F1: nav ابطال | G1: بازدهی nav | H1: AUM | I1: حباب | J1: میزان نقدشوندگی | K1: بازدهی قیمتی | L1: ذخیره سود
A2: 1401/01/31 | B2: فیروزا | C2: 27615 | D2: 13121784 | E2: 362357538977 | F2: 27919 | G2: 0.00082449097 | H2: 5862950392752 | I2: -0.010888642 | J2: =VLOOKUP([1]PYTHON!A2,[1]فیروزا!A:J,10) -> 0.06180464 | K2: 0.00057973115 | L2: 0
A3: 1401/02/31 | B3: فیروزا | C3: 28105 | D3: 5696387 | E3: 160095357589 | F3: 28382 | G3: 0.00074045344 | H3: 7946770203863 | I3: -0.0097597069 | J3: =VLOOKUP([1]PYTHON!A3,[1]فیروزا!A:J,10) -> 0.020145965 | K3: 0.0015323213 | L3: 0
A4: 1401/03/31 | B4: فیروزا | C4: 28602 | D4: 3803423 | E4: 108787094173 | F4: 28769 | G4: 6.9524107e-05 | H4: 8630570912567 | I4: -0.0058048594 | J4: =VLOOKUP([1]PYTHON!A4,[1]فیروزا!A:J,10) -> 0.012604855 | K4: 0.00055971455 | L4: 0
A5: 1401/04/29 | B5: فیروزا | C5: 29082 | D5: 6103563 | E5: 177501831388 | F5: 29090 | G5: 0.0011356988 | H5: 12217552820557 | I5: -0.00027500859 | J5: =VLOOKUP([1]PYTHON!A5,[1]فیروزا!A:J,10) -> 0.014528428 | K5: 0.00075705437 | L5: 0
A6: 1401/05/31 | B6: فیروزا | C6: 29626 | D6: 71927157 | E6: 2130944983037 | F6: 29557 | G6: 0.0018982407 | H6: 12413551677950 | I6: 0.0023344724 | J6: =VLOOKUP([1]PYTHON!A6,[1]فیروزا!A:J,10) -> 0.1716628 | K6: 0.00057414975 | L6: 0
A7: 1401/06/30 | B7: فیروزا | C7: 30140 | D7: 5658855 | E7: 170555694593 | F7: 30102 | G7: 0.00039880359 | H7: 13244848433634 | I7: 0.0012623746 | J7: =VLOOKUP([1]PYTHON!A7,[1]فیروزا!A:J,10) -> 0.012877134 | K7: 0.00076368828 | L7: -0.0020928842
A8: 1401/07/30 | B8: فیروزا | C8: 30669 | D8: 11646748 | E8: 357194404770 | F8: 30686 | G8: 0.0017301603 | H8: 13035210556539 | I8: -0.00055399857 | J8: =VLOOKUP([1]PYTHON!A8,[1]فیروزا!A:J,10) -> 0.027402273 | K8: 0.0015348442 | L8: -0.0038128137
A9: 1401/08/30 | B9: فیروزا | C9: 31195 | D9: 7193478 | E9: 224400971693 | F9: 31213 | G9: 0.00057701555 | H9: 14760778661483 | I9: -0.00057668279 | J9: =VLOOKUP([1]PYTHON!A9,[1]فیروزا!A:J,10) -> 0.015202516 | K9: 0.00057734869 | L9: 0.002851376
A10: 1401/09/30 | B10: فیروزا | C10: 31768 | D10: 85607266 | E10: 2719535696726 | F10: 31815 | G10: 0.001511002 | H10: 17184266007739 | I10: -0.0014772906 | J10: =VLOOKUP([1]PYTHON!A10,[1]فیروزا!A:J,10) -> 0.15825731 | K10: 0.00081910403 | L10: -0.0012258369
A11: 1401/10/28 | B11: فیروزا | C11: 32316 | D11: 37934821 | E11: 1225893334421 | F11: 32317 | G11: 6.1890763e-05 | H11: 16876206077619 | I11: -3.0943466e-05 | J11: =VLOOKUP([1]PYTHON!A11,[1]فیروزا!A:J,10) -> 0.072640339 | K11: 0.00080520285 | L11: 0.01392456
A12: 1401/11/30 | B12: فیروزا | C12: 32943 | D12: 43809552 | E12: 1443229987824 | F12: 32965 | G12: 0.0033480444 | H12: 20843253501851 | I12: -0.00066737449 | J12: =VLOOKUP([1]PYTHON!A12,[1]فیروزا!A:J,10) -> 0.069242069 | K12: 0.0017637221 | L12: -0.00060670408
A13: 1401/12/28 | B13: فیروزا | C13: 33516 | D13: 19299718 | E13: 646853486408 | F13: 33527 | G13: 0.0003878976 | H13: 20302877023658 | I13: -0.00032809378 | J13: =VLOOKUP([1]PYTHON!A13,[1]فیروزا!A:J,10) -> 0.031860188 | K13: 0.0007464692 | L13: 0.048438572
... A49: 1404/12/27 | B49: فیروزا | C49: 77395 | D49: 145316923 | E49: 11246765921180 | F49: 77333 | G49: 0.0059446381 | H49: 261870745826836 | I49: 0.00080172759 | J49: =VLOOKUP([1]PYTHON!A49,[1]فیروزا!A:J,10) -> 0.042947775 | K49: 0.0070655285 | L49: 0.02029978
A50: 1405/01/31 | B50: فیروزا | C50: 79486 | D50: 140969547 | E50: 11205144200321 | F50: 79468 | G50: 0.0051860659 | H50: 287638142866830 | J50: =E50/H50 -> 0.038955697 | K50: 0.0012092203 | L50: 0.012444791
A51: 1405/02/30 | B51: فیروزا | C51: 81735 | D51: 217274163 | E51: 17758992479192 | F51: 81757 | G51: 0.0016907828 | H51: 286643858762234 | J51: =E51/H51 -> 0.061954903 | K51: 0.0012740258 | L51: 0.014082095
A52: 1405/03/13 | B52: فیروزا | C52: 82785 | D52: 277260346 | E52: 22953136223902 | F52: 82783 | G52: 0.0012699872 | H52: 316449097632745 | J52: =E52/H52 -> 0.072533423 | K52: 0.0012699565 | L52: 0.010812772
A53: 1401/01/31 | B53: یاقوت | C53: 14611 | D53: 3985275 | E53: 58226941471 | F53: 14611 | G53: 6.844627e-05 | H53: 30,168,581,491,839 | I53: =(C53/F53)-1 -> 0 | J53: 0.0019300523 | K53: 0.00047932073 | L53: -0.0088289645
A54: 1401/02/31 | B54: یاقوت | C54: 14828 | D54: 3334306 | E54: 49441391052 | F54: 14828 | G54: 0.0014182481 | H54: 32,450,593,818,183 | I54: =(C54/F54)-1 -> 0 | J54: 0.0015235897 | K54: 0.0014182481 | L54: -0.0022255193
A55: 1401/03/31 | B55: یاقوت | C55: 15061 | D55: 32392248 | E55: 487871864864 | F55: 15058 | G55: 0.0003321597 | H55: 28,629,271,491,912 | I55: =(C55/F55)-1 -> 0.00019922965 | J55: 0.017041016 | K55: 0.00053145552 | L55: 0
A56: 1401/04/29 | B56: یاقوت | C56: 15287 | D56: 11661707 | E56: 178277347200 | F56: 15276 | G56: 0.00045844522 | H56: 27,242,177,049,000 | I56: =(C56/F56)-1 -> 0.00072008379 | J56: 0.0065441667 | K56: 0.001113294 | L56: 0.00026184865
A57: 1401/05/31 | B57: یاقوت | C57: 15531 | D57: 3000906 | E57: 46607156326 | F57: 15525 | G57: 0.00051556358 | H57: 27,503,674,002,884 | I57: =(C57/F57)-1 -> 0.00038647343 | J57: 0.0016945793 | K57: 0.00070876289 | L57: 0.002705314
A58: 1401/06/30 | B58: یاقوت | C58: 15775 | D58: 9906167 | E58: 156269739731 | F58: 15762 | G58: 0.00050780754 | H58: 26,835,988,832,065 | I58: =(C58/F58)-1 -> 0.00082476843 | J58: 0.0058231407 | K58: 0.00095177665 | L58: 0.0088186778
A59: 1401/07/30 | B59: یاقوت | C59: 16016 | D59: 6836766 | E59: 109495797740 | F59: 16014 | G59: 0.001563575 | H59: 22,690,752,280,288 | I59: =(C59/F59)-1 -> 0.00012489072 | J59: 0.0048255693 | K59: 0.001 | L59: 0.00780567
A60: 1401/08/30 | B60: یاقوت | C60: 16267 | D60: 7783283 | E60: 126608671904 | F60: 16264 | G60: 0.00055367579 | H60: 19,826,942,675,919 | I60: =(C60/F60)-1 -> 0.00018445647 | J60: 0.0063856881 | K60: 0.00061511964 | L60: 0.0093457944
A61: 1401/09/30 | B61: یاقوت | C61: 16578 | D61: 15963874 | E61: 264644858497 | F61: 16555 | G61: 0.00048347132 | H61: 14,679,325,453,617 | I61: =(C61/F61)-1 -> 0.0013893084 | J61: 0.018028407 | K61: 0.0012683457 | L61: 0.0064028994
A62: 1401/10/28 | B62: یاقوت | C62: 16824 | D62: 29745319 | E62: 500427249327 | F62: 16802 | G62: 0.00017858206 | H62: 15,303,709,496,904 | I62: =(C62/F62)-1 -> 0.0013093679 | J62: 0.032699735 | K62: 0.0013093679 | L62: 0.019938103
A63: 1401/11/30 | B63: یاقوت | C63: 17099 | D63: 21074716 | E63: 360358095515 | F63: 17085 | G63: 0.0021115608 | H63: 13,179,344,043,981 | I63: =(C63/F63)-1 -> 0.00081943225 | J63: 0.027342643 | K63: 0.0016402085 | L63: 0.016681299
A64: 1401/12/28 | B64: یاقوت | C64: 17631 | D64: 25174429 | E64: 443862308470 | F64: 17588 | G64: 0.00051197452 | H64: 11,753,167,732,496 | I64: =(C64/F64)-1 -> 0.0024448488 | J64: 0.037765334 | K64: 0.0020460358 | L64: 0.03428474
... A100: 1404/12/27 | B100: یاقوت | C100: 40030 | D100: 601822061 | E100: 24091190815550 | F100: 39917 | G100: 0.0028389107 | H100: 382,206,589,613,076 | I100: =(C100/F100)-1 -> 0.0028308741 | J100: 0.063031856 | K100: 0.0034844952 | L100: 0.002747939
A101: 1405/01/31 | B101: یاقوت | C101: 41011 | D101: 307786393 | E101: 12622535385773 | F101: 40955 | G101: 0.0011978683 | H101: 485886440174828 | I101: =(C101/F101)-1 -> 0.0013673544 | J101: =E101/H101 -> 0.025978365 | K101: 0.0013429046 | L101: 0.00039013923
A102: 1405/02/30 | B102: یاقوت | C102: 42163 | D102: 417272321 | E102: 17593329165656 | F102: 42135 | G102: 0 | H102: 475969686359594 | I102: =(C102/F102)-1 -> 0.00066453068 | J102: =E102/H102 -> 0.03696313 | K102: 0.0015678077 | L102: -0.00059293694
A103: 1405/03/13 | B103: یاقوت | C103: 42662 | D103: 400396614 | E103: 17081606004356 | F103: 42596 | G103: 0.0012928704 | H103: 519614791587937 | I103: =(C103/F103)-1 -> 0.0015494413 | J103: =E103/H103 -> 0.032873595 | K103: 0.0015729546 | L103: 0.0048127715
A104: 1401/01/31 | B104: کیان | C104: 34361 | D104: 25982089 | E104: 892773777453 | F104: 34144 | G104: -0.0017249949 | H104: 47,956,014,788,642 | I104: 0.0063554358 | J104: 0.018616513 | K104: 0.0015156373 | L104: -0.0047153233
A105: 1401/02/31 | B105: کیان | C105: 34911 | D105: 33182070 | E105: 1158421423687 | F105: 34923 | G105: 0.0015486535 | H105: 43,758,675,374,128 | I105: -0.00034361309 | J105: 0.026472955 | K105: 0.0016353934 | L105: -0.0071872405
A106: 1401/03/31 | B106: کیان | C106: 35524 | D106: 16324530 | E106: 579904859366 | F106: 35274 | G106: -0.0028551237 | H106: 43,489,071,470,228 | I106: 0.0070873731 | J106: 0.013334496 | K106: 0.00059149931 | L106: -0.0069172762
A107: 1401/04/29 | B107: کیان | C107: 36142 | D107: 30451935 | E107: 1100592899270 | F107: 35620 | G107: 0.00216639 | H107: 44,062,571,236,141 | I107: 0.014654688 | J107: 0.024977954 | K107: 0.001052515 | L107: -0.0069062325
A108: 1401/05/31 | B108: کیان | C108: 36823 | D108: 16796216 | E108: 618492269216 | F108: 35970 | G108: 0.00030590395 | H108: 48,530,628,893,389 | I108: 0.023714206 | J108: 0.01274437 | K108: 0.00057062116 | L108: -0.0055323881
A109: 1401/06/30 | B109: کیان | C109: 37427 | D109: 15049304 | E109: 563243398254 | F109: 36392 | G109: -0.00046691752 | H109: 52,764,281,472,548 | I109: 0.028440317 | J109: 0.01067471 | K109: 0.0010431154 | L109: -0.005962849
A110: 1401/07/30 | B110: کیان | C110: 38022 | D110: 32782425 | E110: 1246440792352 | F110: 36852 | G110: 0.0012225935 | H110: 48,714,785,188,171 | I110: 0.031748616 | J110: 0.025586499 | K110: 0.0013167597 | L110: -0.0081135352
...

Sheet Sheet2
A1: تاریخ | B1: نماد
A2: 1401/01/31 | B2: فیروزا
A3: 1401/02/31 | B3: فیروزا
A4: 1401/03/31 | B4: فیروزا
A5: 1401/04/31 | B5: فیروزا
A6: 1401/05/31 | B6: فیروزا
A7: 1401/06/31 | B7: فیروزا
A8: 1401/07/30 | B8: فیروزا
A9: 1401/08/30 | B9: فیروزا
A10: 1401/09/30 | B10: فیروزا
A11: 1401/10/30 | B11: فیروزا
A12: 1401/11/30 | B12: فیروزا
... A145: 1404/12/29 | B145: کیان
B146: آوند
B147: آوند
B148: آوند
B149: آوند
B150: آوند
B151: آوند
B152: آوند
B153: آوند
B154: آوند
B155: آوند
B156: آوند
B157: آوند
... B247: پاسارگاد
